[2025-06-02T20:05:54.933+0000] {taskinstance.py:1956} INFO - Dependencies all met for dep_context=non-requeueable deps ti=<TaskInstance: google_scraper_pipeline.run_scraper manual__2025-06-02T16:36:58.866401+00:00 [queued]>
[2025-06-02T20:05:54.936+0000] {taskinstance.py:1956} INFO - Dependencies all met for dep_context=requeueable deps ti=<TaskInstance: google_scraper_pipeline.run_scraper manual__2025-06-02T16:36:58.866401+00:00 [queued]>
[2025-06-02T20:05:54.937+0000] {taskinstance.py:2170} INFO - Starting attempt 15 of 16
[2025-06-02T20:05:54.942+0000] {taskinstance.py:2191} INFO - Executing <Task(PythonOperator): run_scraper> on 2025-06-02 16:36:58.866401+00:00
[2025-06-02T20:05:54.945+0000] {standard_task_runner.py:60} INFO - Started process 3838 to run task
[2025-06-02T20:05:54.948+0000] {standard_task_runner.py:87} INFO - Running: ['***', 'tasks', 'run', 'google_scraper_pipeline', 'run_scraper', 'manual__2025-06-02T16:36:58.866401+00:00', '--job-id', '31', '--raw', '--subdir', 'DAGS_FOLDER/google_scraper_dag.py', '--cfg-path', '/tmp/tmp8trffjaw']
[2025-06-02T20:05:54.949+0000] {standard_task_runner.py:88} INFO - Job 31: Subtask run_scraper
[2025-06-02T20:05:54.981+0000] {task_command.py:423} INFO - Running <TaskInstance: google_scraper_pipeline.run_scraper manual__2025-06-02T16:36:58.866401+00:00 [running]> on host 4a3ff0e975f7
[2025-06-02T20:05:55.039+0000] {taskinstance.py:2480} INFO - Exporting env vars: AIRFLOW_CTX_DAG_OWNER='***' AIRFLOW_CTX_DAG_ID='google_scraper_pipeline' AIRFLOW_CTX_TASK_ID='run_scraper' AIRFLOW_CTX_EXECUTION_DATE='2025-06-02T16:36:58.866401+00:00' AIRFLOW_CTX_TRY_NUMBER='15' AIRFLOW_CTX_DAG_RUN_ID='manual__2025-06-02T16:36:58.866401+00:00'
[2025-06-02T20:05:55.573+0000] {logging_mixin.py:188} INFO - ‚úÖ Depend√™ncias instaladas com sucesso
[2025-06-02T20:05:55.574+0000] {logging_mixin.py:188} INFO - üì¶ A executar comando: python3 /opt/***/dags/google_scraper/scraping/run_scraper_***.py --dias 1
[2025-06-02T20:05:56.503+0000] {logging_mixin.py:188} INFO - C√≥digo de retorno: 1
[2025-06-02T20:05:56.503+0000] {logging_mixin.py:188} INFO - Resultado: 
[2025-06-02T20:05:56.503+0000] {logging_mixin.py:188} INFO - Erros: Traceback (most recent call last):
  File "/opt/***/dags/google_scraper/scraping/run_scraper_***.py", line 293, in <module>
    @retry(
     ^^^^^
NameError: name 'retry' is not defined. Did you mean: 'repr'?
[2025-06-02T20:05:56.503+0000] {logging_mixin.py:188} INFO - ‚ö†Ô∏è Comando falhou com c√≥digo de retorno 1
[2025-06-02T20:05:56.504+0000] {logging_mixin.py:188} INFO - ‚ö†Ô∏è Erro ao executar comando: Command '['python3', '/opt/***/dags/google_scraper/scraping/run_scraper_***.py', '--dias', '1']' returned non-zero exit status 1.
[2025-06-02T20:05:56.504+0000] {logging_mixin.py:188} INFO - Resultado: 
[2025-06-02T20:05:56.504+0000] {logging_mixin.py:188} INFO - Erro: Traceback (most recent call last):
  File "/opt/***/dags/google_scraper/scraping/run_scraper_***.py", line 293, in <module>
    @retry(
     ^^^^^
NameError: name 'retry' is not defined. Did you mean: 'repr'?
[2025-06-02T20:05:56.504+0000] {logging_mixin.py:188} INFO - ‚ö†Ô∏è Erro em run_scraper: Command '['python3', '/opt/***/dags/google_scraper/scraping/run_scraper_***.py', '--dias', '1']' returned non-zero exit status 1.
[2025-06-02T20:05:57.005+0000] {logging_mixin.py:188} INFO - ‚úÖ Depend√™ncias instaladas com sucesso
[2025-06-02T20:05:57.005+0000] {logging_mixin.py:188} INFO - üì¶ A executar comando: python3 /opt/***/dags/google_scraper/scraping/run_scraper.py --dias 1
[2025-06-02T20:10:24.872+0000] {local_task_job_runner.py:302} WARNING - State of this instance has been externally set to restarting. Terminating instance.
[2025-06-02T20:10:24.878+0000] {process_utils.py:131} INFO - Sending 15 to group 3838. PIDs of all processes in the group: [3878, 3838]
[2025-06-02T20:10:24.879+0000] {process_utils.py:86} INFO - Sending the signal 15 to group 3838
[2025-06-02T20:10:24.880+0000] {taskinstance.py:2450} ERROR - Received SIGTERM. Terminating subprocesses.
[2025-06-02T20:10:24.893+0000] {logging_mixin.py:188} INFO - ‚ö†Ô∏è Erro no fallback run_scraper: Task received SIGTERM signal
[2025-06-02T20:10:24.912+0000] {taskinstance.py:2698} ERROR - Task failed with exception
Traceback (most recent call last):
  File "/opt/airflow/dags/google_scraper_dag.py", line 107, in run_scraper
    return run_script("scraping/run_scraper_airflow.py", dias, date)
           ^^^^^^^^^^^^^^^^^^^^^^^^^^^^^^^^^^^^^^^^^^^^^^^^^^^^^^^^^
  File "/opt/airflow/dags/google_scraper_dag.py", line 88, in run_script
    raise subprocess.CalledProcessError(
subprocess.CalledProcessError: Command '['python3', '/opt/airflow/dags/google_scraper/scraping/run_scraper_airflow.py', '--dias', '1']' returned non-zero exit status 1.

During handling of the above exception, another exception occurred:

Traceback (most recent call last):
  File "/home/airflow/.local/lib/python3.11/site-packages/airflow/models/taskinstance.py", line 433, in _execute_task
    result = execute_callable(context=context, **execute_callable_kwargs)
             ^^^^^^^^^^^^^^^^^^^^^^^^^^^^^^^^^^^^^^^^^^^^^^^^^^^^^^^^^^^^
  File "/home/airflow/.local/lib/python3.11/site-packages/airflow/operators/python.py", line 199, in execute
    return_value = self.execute_callable()
                   ^^^^^^^^^^^^^^^^^^^^^^^
  File "/home/airflow/.local/lib/python3.11/site-packages/airflow/operators/python.py", line 216, in execute_callable
    return self.python_callable(*self.op_args, **self.op_kwargs)
           ^^^^^^^^^^^^^^^^^^^^^^^^^^^^^^^^^^^^^^^^^^^^^^^^^^^^^
  File "/opt/airflow/dags/google_scraper_dag.py", line 112, in run_scraper
    return run_script("scraping/run_scraper.py", dias, date)
           ^^^^^^^^^^^^^^^^^^^^^^^^^^^^^^^^^^^^^^^^^^^^^^^^^
  File "/opt/airflow/dags/google_scraper_dag.py", line 80, in run_script
    result = subprocess.run(cmd, capture_output=True, text=True)
             ^^^^^^^^^^^^^^^^^^^^^^^^^^^^^^^^^^^^^^^^^^^^^^^^^^^
  File "/usr/local/lib/python3.11/subprocess.py", line 550, in run
    stdout, stderr = process.communicate(input, timeout=timeout)
                     ^^^^^^^^^^^^^^^^^^^^^^^^^^^^^^^^^^^^^^^^^^^
  File "/usr/local/lib/python3.11/subprocess.py", line 1209, in communicate
    stdout, stderr = self._communicate(input, endtime, timeout)
                     ^^^^^^^^^^^^^^^^^^^^^^^^^^^^^^^^^^^^^^^^^^
  File "/usr/local/lib/python3.11/subprocess.py", line 2113, in _communicate
    ready = selector.select(timeout)
            ^^^^^^^^^^^^^^^^^^^^^^^^
  File "/usr/local/lib/python3.11/selectors.py", line 415, in select
    fd_event_list = self._selector.poll(timeout)
                    ^^^^^^^^^^^^^^^^^^^^^^^^^^^^
  File "/home/airflow/.local/lib/python3.11/site-packages/airflow/models/taskinstance.py", line 2452, in signal_handler
    raise AirflowException("Task received SIGTERM signal")
airflow.exceptions.AirflowException: Task received SIGTERM signal
[2025-06-02T20:10:24.919+0000] {taskinstance.py:1138} INFO - Marking task as UP_FOR_RETRY. dag_id=google_scraper_pipeline, task_id=run_scraper, execution_date=20250602T163658, start_date=20250602T200554, end_date=20250602T201024
[2025-06-02T20:10:24.928+0000] {standard_task_runner.py:107} ERROR - Failed to execute job 31 for task run_scraper (Task received SIGTERM signal; 3838)
[2025-06-02T20:10:24.936+0000] {process_utils.py:79} INFO - Process psutil.Process(pid=3838, status='terminated', exitcode=1, started='20:05:54') (3838) terminated with exit code 1
[2025-06-02T20:10:24.936+0000] {process_utils.py:79} INFO - Process psutil.Process(pid=3878, status='terminated', started='20:05:56') (3878) terminated with exit code None
