[2025-06-02T17:10:43.644+0000] {task_context_logger.py:104} ERROR - Executor reports task instance <TaskInstance: google_scraper_pipeline.run_scraper manual__2025-06-02T16:36:58.866401+00:00 [queued]> finished (failed) although the task says it's queued. (Info: None) Was the task killed externally?
