[2025-06-02T15:22:48.206+0000] {taskinstance.py:1157} INFO - Dependencies all met for dep_context=non-requeueable deps ti=<TaskInstance: google_scraper_pipeline.run_scraper manual__2025-06-02T15:09:07.943661+00:00 [queued]>
[2025-06-02T15:22:48.210+0000] {taskinstance.py:1157} INFO - Dependencies all met for dep_context=requeueable deps ti=<TaskInstance: google_scraper_pipeline.run_scraper manual__2025-06-02T15:09:07.943661+00:00 [queued]>
[2025-06-02T15:22:48.210+0000] {taskinstance.py:1359} INFO - Starting attempt 10 of 11
[2025-06-02T15:22:48.216+0000] {taskinstance.py:1380} INFO - Executing <Task(PythonOperator): run_scraper> on 2025-06-02 15:09:07.943661+00:00
[2025-06-02T15:22:48.219+0000] {standard_task_runner.py:57} INFO - Started process 1348 to run task
[2025-06-02T15:22:48.221+0000] {standard_task_runner.py:84} INFO - Running: ['***', 'tasks', 'run', 'google_scraper_pipeline', 'run_scraper', 'manual__2025-06-02T15:09:07.943661+00:00', '--job-id', '11', '--raw', '--subdir', 'DAGS_FOLDER/google_scraper_dag.py', '--cfg-path', '/tmp/tmpmg5ojev7']
[2025-06-02T15:22:48.222+0000] {standard_task_runner.py:85} INFO - Job 11: Subtask run_scraper
[2025-06-02T15:22:48.249+0000] {task_command.py:415} INFO - Running <TaskInstance: google_scraper_pipeline.run_scraper manual__2025-06-02T15:09:07.943661+00:00 [running]> on host 1457ea4f74d2
[2025-06-02T15:22:48.285+0000] {taskinstance.py:1660} INFO - Exporting env vars: AIRFLOW_CTX_DAG_OWNER='***' AIRFLOW_CTX_DAG_ID='google_scraper_pipeline' AIRFLOW_CTX_TASK_ID='run_scraper' AIRFLOW_CTX_EXECUTION_DATE='2025-06-02T15:09:07.943661+00:00' AIRFLOW_CTX_TRY_NUMBER='10' AIRFLOW_CTX_DAG_RUN_ID='manual__2025-06-02T15:09:07.943661+00:00'
[2025-06-02T15:22:48.286+0000] {logging_mixin.py:151} INFO - üì¶ Executing command: python3 /opt/***/dags/google_scraper/scraping/run_scraper_***.py --dias 1
[2025-06-02T15:22:48.388+0000] {logging_mixin.py:151} INFO - Return code: 1
[2025-06-02T15:22:48.388+0000] {logging_mixin.py:151} INFO - Output: Could not import run_scraper module
[2025-06-02T15:22:48.388+0000] {logging_mixin.py:151} INFO - ‚ö†Ô∏è Command failed with return code 1
[2025-06-02T15:22:48.389+0000] {logging_mixin.py:151} INFO - ‚ö†Ô∏è Error executing command: Command '['python3', '/opt/***/dags/google_scraper/scraping/run_scraper_***.py', '--dias', '1']' returned non-zero exit status 1.
[2025-06-02T15:22:48.389+0000] {logging_mixin.py:151} INFO - Output: Could not import run_scraper module
[2025-06-02T15:22:48.389+0000] {logging_mixin.py:151} INFO - Error output: 
[2025-06-02T15:22:48.389+0000] {logging_mixin.py:151} INFO - ‚ö†Ô∏è Error in run_scraper: Command '['python3', '/opt/***/dags/google_scraper/scraping/run_scraper_***.py', '--dias', '1']' returned non-zero exit status 1.
[2025-06-02T15:22:48.389+0000] {logging_mixin.py:151} INFO - üì¶ Executing command: python3 /opt/***/dags/google_scraper/scraping/run_scraper.py --dias 1
[2025-06-02T15:22:48.462+0000] {logging_mixin.py:151} INFO - Return code: 1
[2025-06-02T15:22:48.462+0000] {logging_mixin.py:151} INFO - Output: 
[2025-06-02T15:22:48.462+0000] {logging_mixin.py:151} INFO - Errors: Traceback (most recent call last):
  File "/opt/***/dags/google_scraper/scraping/run_scraper.py", line 4, in <module>
    import feedparser
ModuleNotFoundError: No module named 'feedparser'
[2025-06-02T15:22:48.463+0000] {logging_mixin.py:151} INFO - ‚ö†Ô∏è Command failed with return code 1
[2025-06-02T15:22:48.463+0000] {logging_mixin.py:151} INFO - ‚ö†Ô∏è Error executing command: Command '['python3', '/opt/***/dags/google_scraper/scraping/run_scraper.py', '--dias', '1']' returned non-zero exit status 1.
[2025-06-02T15:22:48.463+0000] {logging_mixin.py:151} INFO - Output: 
[2025-06-02T15:22:48.463+0000] {logging_mixin.py:151} INFO - Error output: Traceback (most recent call last):
  File "/opt/***/dags/google_scraper/scraping/run_scraper.py", line 4, in <module>
    import feedparser
ModuleNotFoundError: No module named 'feedparser'
[2025-06-02T15:22:48.463+0000] {logging_mixin.py:151} INFO - ‚ö†Ô∏è Error in fallback run_scraper: Command '['python3', '/opt/***/dags/google_scraper/scraping/run_scraper.py', '--dias', '1']' returned non-zero exit status 1.
[2025-06-02T15:22:48.463+0000] {taskinstance.py:1935} ERROR - Task failed with exception
Traceback (most recent call last):
  File "/opt/airflow/dags/google_scraper_dag.py", line 76, in run_scraper
    return run_script("scraping/run_scraper_airflow.py", dias, date)
  File "/opt/airflow/dags/google_scraper_dag.py", line 57, in run_script
    raise subprocess.CalledProcessError(
subprocess.CalledProcessError: Command '['python3', '/opt/airflow/dags/google_scraper/scraping/run_scraper_airflow.py', '--dias', '1']' returned non-zero exit status 1.

During handling of the above exception, another exception occurred:

Traceback (most recent call last):
  File "/home/airflow/.local/lib/python3.8/site-packages/airflow/operators/python.py", line 192, in execute
    return_value = self.execute_callable()
  File "/home/airflow/.local/lib/python3.8/site-packages/airflow/operators/python.py", line 209, in execute_callable
    return self.python_callable(*self.op_args, **self.op_kwargs)
  File "/opt/airflow/dags/google_scraper_dag.py", line 81, in run_scraper
    return run_script("scraping/run_scraper.py", dias, date)
  File "/opt/airflow/dags/google_scraper_dag.py", line 57, in run_script
    raise subprocess.CalledProcessError(
subprocess.CalledProcessError: Command '['python3', '/opt/airflow/dags/google_scraper/scraping/run_scraper.py', '--dias', '1']' returned non-zero exit status 1.
[2025-06-02T15:22:48.469+0000] {taskinstance.py:1398} INFO - Marking task as UP_FOR_RETRY. dag_id=google_scraper_pipeline, task_id=run_scraper, execution_date=20250602T150907, start_date=20250602T152248, end_date=20250602T152248
[2025-06-02T15:22:48.475+0000] {standard_task_runner.py:104} ERROR - Failed to execute job 11 for task run_scraper (Command '['python3', '/opt/airflow/dags/google_scraper/scraping/run_scraper.py', '--dias', '1']' returned non-zero exit status 1.; 1348)
[2025-06-02T15:22:48.481+0000] {local_task_job_runner.py:228} INFO - Task exited with return code 1
[2025-06-02T15:22:48.493+0000] {taskinstance.py:2776} INFO - 0 downstream tasks scheduled from follow-on schedule check
